Workbook
Name \0: #REF!
Name \A: #REF!
Name \b: #REF!
Name \c: #REF!
Name \CF1: #N/A
Name \CF2: #N/A
Name \CF3: #REF!
Name \CF4: #REF!
Name \d: #REF!
Name \e: #REF!
Name \f: #REF!
Name \g: #REF!
Name \h: #REF!
Name \HL1: #N/A
Name \HL2: #N/A
Name \HL3: #REF!
Name \HL4: #REF!
Name \i: #REF!
Name \j: #REF!
Name \k: #REF!
Name \l: #REF!
Name \lily: #REF!
Name \m: #REF!
Name \n: #REF!
Name \NA1: #N/A
Name \NA2: #N/A
Name \NA3: #N/A
Name \NA4: #REF!
Name \o: #REF!
Name \p: #REF!
Name \P_1: #REF!
Name \PL1: #N/A
Name \PL2: #N/A
Name \PL3: #N/A
Name \PL4: #REF!
Name \q: #REF!
Name \r: #REF!
Name \s: #REF!
Name \t: #REF!
Name \u: #REF!
Name \v: #REF!
Name \w: #REF!
Name \x: #REF!
Name \y: #REF!
Name \z: #REF!
Name _: #REF!
Name _________________________GoA1: #N/A
Name _______________________GoA1: #N/A
Name _____________________GoA1: #N/A
Name ____________________GoA1: #N/A
Name ___________________GoA1: #N/A
Name _________________GoA1: #N/A
Name ________________GoA1: #N/A
Name _______________GoA1: #N/A
Name ______________GoA1: #N/A
Name _____________GoA1: #N/A
Name ____________GoA1: #REF!
Name ___________CUA1: #REF!
Name ___________DAT12: #REF!
Name ___________DAT13: #REF!

Sheet SFP254_Introduction
B2: Introduction: SFP254 Pre-CER & CER ROI Financial Evaluation
B4: A | C4: SFP254 Financial model is an adaptation of existing SFP251 Financial Model, after removing various functionalities in SFP251 that are rarely used. The calculation of ROI and Funding requirement (gap) is basically unchanged. SFP254 will replace SFP251. The template is available in 3 file types:
C5: 1) SFP254 Standalone template, where all data input is made in the SFP254 template.
C6: 2) SFP254-CQSC Integrated template, where
C7: a) Revenue, cost, capex and tooling information are linked from the CQSC (standard template from Global Costing Team) and
C8: b) Other inputs are entered directly in SFP254 template (PNL adjustments, inventory requirements, acct receivables, taxation, etc.). The integrated template provides a preliminary estimate of ROI & Funding Gap for feasibility assessment or budgetary quote.
C9: 1) SFP254 Multi-program template, where you can consolidate multiple programs or Parts into a single financial evaluation.
B11: B | C11: Site Finance Review. SFP254 requires Finance review and validation for binding quotes that requires capex commitment or amortization (refer to RFQ ALM) and prior to Leve; 3 review.
B12: C | C12: Please ensure SOP Year and Month are entered (input field YYYY and MM located at the top header of the template) for all program. For Multi-Program projects, the SOP year and date must also be entered in the Consolidation Worksheet, and must be consistent for all programs within the project
B13: D | C13: Multi-Program projects. You can consolidate the financial evaluation of multiple programs/Parts into a single statement using the SFP254_Multiprogram template. Simply insert a copy of the completed SFP254 for individual programs from the CQSC file and/or standalone template into the Consolidation template file. Insert the program level SFP254 in between worksheet "Bgn>>" and "<<End". The Consol worksheet will then pick-up data from all SFP254 worksheets in the range, and display the consolidated results, including the consolidated GP% and ROI
B14: E | C14: Inter-Company purchases. If your project includes purchases between different ENNOVI/Interplex Sites (parts, components or tooling/automation), please use the standard cost when preparing the SFP254 model (not the inter-co selling price). The standard cost can be obtained from the site. This will ensure inter-co mark-ups are not compounded into the final total cost of the program.
B15: F | C15: Treatment of Tooling and Automation Lines The financial presentation of tooling and automation lines is subject to financial reporting standards/rules i.e. whether it is Tooling COS, Amortization Expense or Capex. Any deviations requires prior written exemption from CFO. The reporting standards are based on the ownership, contractual terms with customer, and operational application of the asset. See below for details.
D16: Application & Contract Terms | E16: Financial Treatment
C17: Tooling, Molds, Jigs, Fixures | D17: All toolings, molds, jigs, fixures in general | E17: Tooling COS
D18: Amortized in Parts price, pre-agree Tool price & amortization basis, customer Liability for unamortized balance | E18: Amortization Expense (Indirect COS)
C20: Automation Line | D20: Program Specific, and/or dedicated to specific customers | E20: Tooling COS. Exemption require Level 3 approval
D21: Program Specific, and/or dedicated to specific customers. Amortized in Parts price, pre-agreed Automation price & amortization basis, customer Liability for unamortized balance | E21: Amortization Expense (Indirect COS). Exemption require Level 3 approval
D22: Generic application, technically and commercially practical to change over to other programs. Asset ownership by ENNOVI/Interplex | E22: Capex, subject to CER approval
B24: G | C24: Tooling COS (PNL). Tooling COS in the PNL is the default treatment of all Tooling cost and program specific automation line. The tooling or automation line is generally specific to program, and often owned by customer (purchased via PO). Due to the difficulties in repurposing program specific tools/automation to other programs, such expenditure are regarded as Tooling COS. For program specific automation line, classification as capex require CFO exemption approval. Tooling COS (used to record tooling and automation line cost) must be booked in PNL at PPAP together with any sales revenue fully paid by customer up to PPAP (usually as stated in PO). If Tooling is Loss making (cost is greater than customer price), then Loss is recognized immediately upon acceptance of customer PO.
B25: H | C25: Amortization Expense, apportioned based on years or volume. This expense is recognized in Indirect COS in the Parts PNL. Customer Tool/Automation contractual terms must satisfy these criteria. 1. Customer has agreed to Tool/Automation Selling Price and Amortization basis in writing (e.g. in PO or Purchase Contract) 2. Amortization (including relevant mark-up) has been factored into Part Price 3. Customer have contractual Liability for payment of any unamortized balance 4. ENNOVI/Interplex retain custody and control of the physical asset until fully amortized (paid by customer). Refer Baseline Quotation Template 2.0 Amortization. If criteria not met, cost of customer's tooling must be recorded in Tooling COS PNL upon PPAP or PO acceptance (if loss making project). Deviation requires CFO's prior written exemption. Quotations with amortization terms required Level 3 RFQ approval (if Cost > $500K per RFQ ALM). Amortization period should not exceed 3 years from SOP or max 5 years (for v.large & strategic programs). Cost must be fully amortized or otherwise, paid-up by customer.
B26: I | C26: Capex. To qualify as Capex, the expenditures (production machines, generic automation*, etc.) must satisfy these criteria: 1. ENNOVI/Interplex has legal ownership, custody and control of the asset 2. Asset must be a physically identifiable item, used to generate income with useful life of min 2 years (e.g. machine/ automation, building, infrastructure, etc.) 3. Asset has high generic design content and application i.e. suitable for use or change over to other programs in site's core business 4. ENNOVI/Interplex has the right to use the asset for any customers or programs, if practicable Any deviation requires CFO prior written exemption. An approved CER must be obtained for all capex. *For program specific automation line, classification as capex require CFO exemption approval (default treatment is Tooling COS).
C30: Asset Categories | D30: Standardized Depreciation Life | E30: Capex Items (examples)
C31: Select…
C32: Production Machines | D32: 10 | E32: All production machines including Stamping, Molding, Plating, Cold Forging, Machining, etc. EXCLUDE accessories and ancillary equipment
C33: Production Ancillary Equipment | D33: 5 | E33: Production machine accessories and ancillary equipment including feeders,
C34: Production Machine Overhauls / Major Maint. | D34: 3 | E34: Overhauls of existing production machines, subject to criteria defined in SOP – Production Machines Maintenance & Overhauls dd 15042022
C35: Factory Equipment (Non-Production Machines) | D35: 8 | E35: All factory machines and equipment other than Production Machines e.g. Overhead Cranes, Forklifts, Compressor, electricals, Aircon, material handling, storage, etc.
C36: Assembly & Packaging Equipment | D36: 10 | E36: Assembly lines and packaging related
C37: Automation Equipment | D37: 3 | E37: Robots, Cobots, AI, cameras, camera tracks, Vision Systems, CCD Inspection, Coil scan vision, product inspection automation, etc.
C38: Leasehold Land | D38: 50 | E38: Leasehold land and building
C39: Building Improvement / Renovations | D39: 10 | E39: All improvements & renovations made to existing building / facilities (both freehold and leasehold)
C40: ENNOVI/Interplex proprietary tooling (presss-fit) | D40: 3 | E40: ENNOVI/Interplex owned tooling for proprietary or standard catalog products only (avail to all customers, non-program specific)
C41: R&D Equipment & Measuring Devises | D41: 3 | E41: Lab/research eqpt, facilities, Gauges, callipers, 3Dlaser scan, 2D scan, VMM/ CMM, in-process comparators, Anodizing Layer hardness Checker, Magnification Scope, IMM measuring equipment, Smartscope for OHC & CA operations, Speed measuring projector, Surface Roughness Measuring eqpt, Keyence's inspection units.
C42: Computer Hware & Software | D42: 3 | E42: All computer hardwares and softwares
C43: Vehicles | D43: 8 | E43: All vehicles
C44: Asset Transfer between Sites | D44: 4 | E44: All production machines asset transfers between Sites

Sheet SFP254v1.5_CONSOLIDATION
N6: CONSOLIDATION TEMPLATE
I7: Pre-CER / CER Financial Evaluation | K7: SFP#254 v1.5_16-04-2024
J8: Project: - | K8: [Prepared by] | L8: Currency:
J9: ENNOVI/Interplex Production Site: | K9: (Consolidation Template) | L9: Note: USD Presentatn in Sectn 9, Charts in Sectn 10
J10: Overall Check | L10: =IF(OR(L11=0,L11="",L12=0,L12=""),"WARNING: Must enter SOP YYYY & MM. SAME for all Prog","OK, SOP date entered") -> OK, SOP date entered | N10: =IF(AND(N220="OK",N221="OK",N241="OK",N255="OK",N305="OK",$K$49="OK,Fully Amortized"),"OK","Wrong") -> OK | O10: =IF(AND(O220="OK",O221="OK",O241="OK",O255="OK",O305="OK"),"OK","Wrong") -> OK | P10: =IF(AND(P220="OK",P221="OK",P241="OK",P255="OK",P305="OK"),"OK","Wrong") -> OK | Q10: =IF(AND(Q220="OK",Q221="OK",Q241="OK",Q255="OK",Q305="OK"),"OK","Wrong") -> OK | R10: =IF(AND(R220="OK",R221="OK",R241="OK",R255="OK",R305="OK"),"OK","Wrong") -> OK | S10: =IF(AND(S220="OK",S221="OK",S241="OK",S255="OK",S305="OK"),"OK","Wrong") -> OK | T10: =IF(AND(T220="OK",T221="OK",T241="OK",T255="OK",T305="OK"),"OK","Wrong") -> OK | U10: =IF(AND(U220="OK",U221="OK",U241="OK",U255="OK",U305="OK"),"OK","Wrong") -> OK | V10: =IF(AND(V220="OK",V221="OK",V241="OK",V255="OK",V305="OK"),"OK","Wrong") -> OK | ... AC10: =IF(AND(AC220="OK",AC221="OK",AC241="OK",AC255="OK",AC305="OK"),"OK","Wrong") -> OK
J11: =L8 -> Currency: | K11: SOP Cal Year: | L11: 2025 | N11: =L11-1 -> 2024 | O11: =N11+1 -> 2025 | P11: =O11+1 -> 2026 | Q11: =P11+1 -> 2027 | R11: =Q11+1 -> 2028 | S11: =R11+1 -> 2029 | T11: =S11+1 -> 2030 | U11: =T11+1 -> 2031 | V11: =U11+1 -> 2032 | W11: =V11+1 -> 2033 | X11: =IF(W11=0,0,W11+1) -> 2034 | Y11: =IF(X11=0,0,X11+1) -> 2035 | Z11: =IF(Y11=0,0,Y11+1) -> 2036 | AA11: =IF(Z11=0,0,Z11+1) -> 2037 | AB11: =IF(AA11=0,0,AA11+1) -> 2038 | AC11: =IF(AB11=0,0,AB11+1) -> 2039
K12: SOP Cal Mth: | L12: 12 | N12: Calendar Year | O12: =N12 -> Calendar Year | P12: =O12 -> Calendar Year | Q12: =P12 -> Calendar Year | R12: =Q12 -> Calendar Year | S12: =R12 -> Calendar Year | T12: =S12 -> Calendar Year | U12: =T12 -> Calendar Year | V12: =U12 -> Calendar Year | ... AC12: =AB12 -> Calendar Year
I14: 1 | J14: Project Summary & Investment Evaluation | L14: TOTAL
I15: A | J15: Project PNL & Funding | L15: Project Total
J16: Revenue - Parts | K16: ="Years of Rev: "&COUNTIF(N16:AC16,">0")&" yrs" -> Years of Rev: 0 yrs | L16: =SUM(N16:AC16) -> 0 | N16: =N118 -> 0 | O16: =O118 -> 0 | P16: =P118 -> 0 | Q16: =Q118 -> 0 | R16: =R118 -> 0 | S16: =S118 -> 0 | T16: =T118 -> 0 | U16: =U118 -> 0 | ... AC16: =AC118 -> 0
J17: COPA% | L17: =K125 -> 0 | N17: =N125 -> 0 | O17: =O125 -> 0 | P17: =P125 -> 0 | Q17: =Q125 -> 0 | R17: =R125 -> 0 | S17: =S125 -> 0 | T17: =T125 -> 0 | U17: =U125 -> 0 | ... AC17: =AC125 -> 0
J18: Gross Profit | L18: =SUM(N18:AC18) -> 0 | N18: =N153 -> 0 | O18: =O153 -> 0 | P18: =P153 -> 0 | Q18: =Q153 -> 0 | R18: =R153 -> 0 | S18: =S153 -> 0 | T18: =T153 -> 0 | U18: =U153 -> 0 | ... AC18: =AC153 -> 0
J19: GP % | L19: =IFERROR(L18/L$16,0) -> 0 | N19: =IFERROR(N18/N16,) -> 0 | O19: =IFERROR(O18/O16,) -> 0 | P19: =IFERROR(P18/P16,) -> 0 | Q19: =IFERROR(Q18/Q16,) -> 0 | R19: =IFERROR(R18/R16,) -> 0 | S19: =IFERROR(S18/S16,) -> 0 | T19: =IFERROR(T18/T16,) -> 0 | U19: =IFERROR(U18/U16,) -> 0 | ... AC19: =IFERROR(AC18/AC16,) -> 0
J20: EBITDA (Parts + Tooling) | L20: =SUM(N20:AC20) -> 0 | N20: =N162 -> 0 | O20: =O162 -> 0 | P20: =P162 -> 0 | Q20: =Q162 -> 0 | R20: =R162 -> 0 | S20: =S162 -> 0 | T20: =T162 -> 0 | U20: =U162 -> 0 | ... AC20: =AC162 -> 0
J21: EBITDA% of total revenue (Parts + Tooling) | L21: =IFERROR(L20/(L16+K139),0) -> 0 | N21: =IFERROR(N20/(N16+N139),0) -> 0 | O21: =IFERROR(O20/(O16+O139),0) -> 0 | P21: =IFERROR(P20/(P16+P139),0) -> 0 | Q21: =IFERROR(Q20/(Q16+Q139),0) -> 0 | R21: =IFERROR(R20/(R16+R139),0) -> 0 | S21: =IFERROR(S20/(S16+S139),0) -> 0 | T21: =IFERROR(T20/(T16+T139),0) -> 0 | U21: =IFERROR(U20/(U16+U139),0) -> 0 | ... AC21: =IFERROR(AC20/(AC16+AC139),0) -> 0
J22: EBIT% of total revenue (Parts + Tooling) | L22: =K166 -> 0 | N22: =N166 -> 0 | O22: =O166 -> 0 | P22: =P166 -> 0 | Q22: =Q166 -> 0 | R22: =R166 -> 0 | S22: =S166 -> 0 | T22: =T166 -> 0 | U22: =U166 -> 0 | ... AC22: =AC166 -> 0
J23: Project Cash Flow (Operations, WC & Investments) | L23: =SUM(N23:AC23) -> 0 | N23: =N324 -> 0 | O23: =O324 -> 0 | P23: =P324 -> 0 | Q23: =Q324 -> 0 | R23: =R324 -> 0 | S23: =S324 -> 0 | T23: =T324 -> 0 | U23: =U324 -> 0 | ... AC23: =AC324 -> 0
J24: Project Investment - Capex | L24: =SUM(N24:AC24) -> 0 | N24: =N70 -> 0 | O24: =O70 -> 0 | P24: =P70 -> 0 | Q24: =Q70 -> 0 | R24: =R70 -> 0 | S24: =S70 -> 0 | T24: =T70 -> 0 | U24: =U70 -> 0 | ... AC24: =AC70 -> 0
J25: Project Investment - Tool Deficit/Invest + Amortization (if any) | L25: =SUM(N25:AC25) -> 0 | N25: =SUM(N73,N74) -> 0 | O25: =SUM(O73,O74) -> 0 | P25: =SUM(P73,P74) -> 0 | Q25: =SUM(Q73,Q74) -> 0 | R25: =SUM(R73,R74) -> 0 | S25: =SUM(S73,S74) -> 0 | T25: =SUM(T73,T74) -> 0 | U25: =SUM(U73,U74) -> 0 | ... AC25: =SUM(AC73,AC74) -> 0
J26: =IF(L75>0,"Annual Funding Gap (including IC asset transfer)","Annual Funding Gap") -> Annual Funding Gap | L26: =SUM(N26:AC26) -> 0 | N26: =-N65 -> 0 | O26: =-O65 -> 0 | P26: =-P65 -> 0 | Q26: =-Q65 -> 0 | R26: =-R65 -> 0 | S26: =-S65 -> 0 | T26: =-T65 -> 0 | U26: =-U65 -> 0 | ... AC26: =-AC65 -> 0
J27: =IF(L75>0,"Peak Funding Gap (including IC asset transfer)","Peak Funding Gap") -> Peak Funding Gap | L27: =MIN(N27:AC27) -> 0 | N27: =N274 -> 0 | O27: =O274 -> 0 | P27: =P274 -> 0 | Q27: =Q274 -> 0 | R27: =R274 -> 0 | S27: =S274 -> 0 | T27: =T274 -> 0 | U27: =U274 -> 0 | ... AC27: =AC274 -> 0
J29: Other Key Metrics:
J30: Internal Cost Improvemt/(Deteriortn):Matrl + Process | K30: Inputed in PNL/ROI | L30: =SUM(N30:AC30) -> 0 | N30: =SUM(N123,N132) -> 0 | O30: =SUM(O123,O132) -> 0 | P30: =SUM(P123,P132) -> 0 | Q30: =SUM(Q123,Q132) -> 0 | R30: =SUM(R123,R132) -> 0 | S30: =SUM(S123,S132) -> 0 | T30: =SUM(T123,T132) -> 0 | U30: =SUM(U123,U132) -> 0 | ... AC30: =SUM(AC123,AC132) -> 0
J31: Excess Working Capital Charge, if any | K31: =IF(P107="Yes","Imputed in ROI","Not imputed in ROI") -> Not imputed in ROI | L31: =SUM(N31:AC31) -> 0 | N31: =IF(N167>0,0,N167) -> 0 | O31: =IF(O167>0,0,O167) -> 0 | P31: =IF(P167>0,0,P167) -> 0 | Q31: =IF(Q167>0,0,Q167) -> 0 | R31: =IF(R167>0,0,R167) -> 0 | S31: =IF(S167>0,0,S167) -> 0 | T31: =IF(T167>0,0,T167) -> 0 | U31: =IF(U167>0,0,U167) -> 0 | ... AC31: =IF(AC167>0,0,AC167) -> 0
I33: B | J33: Project Returns
J34: Cumulative Project Cash Flow (CPCF) | K34: =IFERROR(CONCATENATE("CPCF Multiple: ",ROUND(L34/L65,1),"x"),"MOIC Multiple") -> MOIC Multiple | L34: =AC34 -> 0 | N34: =N325 -> 0 | O34: =O325 -> 0 | P34: =P325 -> 0 | Q34: =Q325 -> 0 | R34: =R325 -> 0 | S34: =S325 -> 0 | T34: =T325 -> 0 | U34: =U325 -> 0 | ... AC34: =AC325 -> 0
J35: ROI (Payback Period) Years | L35: =IF($L$335="No Full Recovery","No Full Recovery",CONCATENATE(ROUND(SUM(N326:AC326),1)," yrs")) -> 0 yrs | N35: =IF($L$335="No Full Recovery","",ROUND(N326,2)&" yrs") -> 0 yrs | O35: =IF($L$335="No Full Recovery","",ROUND(O326,2)&" yrs") -> 0 yrs | P35: =IF($L$335="No Full Recovery","",ROUND(P326,2)&" yrs") -> 0 yrs | Q35: =IF($L$335="No Full Recovery","",ROUND(Q326,2)&" yrs") -> 0 yrs | R35: =IF($L$335="No Full Recovery","",ROUND(R326,2)&" yrs") -> 0 yrs | S35: =IF($L$335="No Full Recovery","",ROUND(S326,2)&" yrs") -> 0 yrs | T35: =IF($L$335="No Full Recovery","",ROUND(T326,2)&" yrs") -> 0 yrs | U35: =IF($L$335="No Full Recovery","",ROUND(U326,2)&" yrs") -> 0 yrs | ... AC35: =IF($L$335="No Full Recovery","",ROUND(AC326,2)&" yrs") -> 0 yrs
J36: Net Present Value (NPV) | K36: =CONCATENATE("WACC@",$L$98*100,"%") -> WACC@15% | L36: =AC36 -> 0 | N36: =SUM($N327:N327) -> 0 | O36: =SUM($N327:O327) -> 0 | P36: =SUM($N327:P327) -> 0 | Q36: =SUM($N327:Q327) -> 0 | R36: =SUM($N327:R327) -> 0 | S36: =SUM($N327:S327) -> 0 | T36: =SUM($N327:T327) -> 0 | U36: =SUM($N327:U327) -> 0 | ... AC36: =SUM($N327:AC327) -> 0
K37: =CONCATENATE("IRR: ",ROUND($L$334*100,1),"%") -> IRR: 0%
I38: C | J38: Working Capital (Annual Average) | L38: =IFERROR(AVERAGEIF(O38:AC38,">100",O38:AC38),) -> 0 | N38: =SUM(N40:N48)-N41 -> 0 | O38: =SUM(O40:O48)-O41 -> 0 | P38: =SUM(P40:P48)-P41 -> 0 | Q38: =SUM(Q40:Q48)-Q41 -> 0 | R38: =SUM(R40:R48)-R41 -> 0 | S38: =SUM(S40:S48)-S41 -> 0 | T38: =SUM(T40:T48)-T41 -> 0 | U38: =SUM(U40:U48)-U41 -> 0 | ... AC38: =SUM(AC40:AC48)-AC41 -> 0
J39: WC % Revenue | L39: =IFERROR(SUM(N38:AC38)/SUM(N16:AC16),"") | N39: =IFERROR(N38/N16,"") | O39: =IFERROR(O38/O16,"") | P39: =IFERROR(P38/P16,"") | Q39: =IFERROR(Q38/Q16,"") | R39: =IFERROR(R38/R16,"") | S39: =IFERROR(S38/S16,"") | T39: =IFERROR(T38/T16,"") | U39: =IFERROR(U38/U16,"") | ... AC39: =IFERROR(AC38/AC16,"")
J40: Accounts Receivable | L40: =IFERROR(AVERAGEIF(N40:AC40,">0",N40:AC40),) -> 0 | N40: =N200 -> 0 | O40: =O200 -> 0 | P40: =P200 -> 0 | Q40: =Q200 -> 0 | R40: =R200 -> 0 | S40: =S200 -> 0 | T40: =T200 -> 0 | U40: =U200 -> 0 | ... AC40: =AC200 -> 0
J41: Total Inventory | L41: =IFERROR(AVERAGEIF(N41:AC41,">0",N41:AC41),) -> 0 | N41: =SUM(N42:N45) -> 0 | O41: =SUM(O42:O45) -> 0 | P41: =SUM(P42:P45) -> 0 | Q41: =SUM(Q42:Q45) -> 0 | R41: =SUM(R42:R45) -> 0 | S41: =SUM(S42:S45) -> 0 | T41: =SUM(T42:T45) -> 0 | U41: =SUM(U42:U45) -> 0 | ... AC41: =SUM(AC42:AC45) -> 0
J42: Inventory - RM/ PI/ Packg | L42: =IFERROR(AVERAGEIF(N42:AC42,">0",N42:AC42),) -> 0 | N42: =N201 -> 0 | O42: =O201 -> 0 | P42: =P201 -> 0 | Q42: =Q201 -> 0 | R42: =R201 -> 0 | S42: =S201 -> 0 | T42: =T201 -> 0 | U42: =U201 -> 0 | ... AC42: =AC201 -> 0
J43: Inventory- WIP | L43: =IFERROR(AVERAGEIF(N43:AC43,">0",N43:AC43),) -> 0 | N43: =N202 -> 0 | O43: =O202 -> 0 | P43: =P202 -> 0 | Q43: =Q202 -> 0 | R43: =R202 -> 0 | S43: =S202 -> 0 | T43: =T202 -> 0 | U43: =U202 -> 0 | ... AC43: =AC202 -> 0
J44: Inventory FGs - Stock for ENNOVI/Interplex's req'mt | L44: =IFERROR(AVERAGEIF(N44:AC44,">0",N44:AC44),) -> 0 | N44: =N203 -> 0 | O44: =O203 -> 0 | P44: =P203 -> 0 | Q44: =Q203 -> 0 | R44: =R203 -> 0 | S44: =S203 -> 0 | T44: =T203 -> 0 | U44: =U203 -> 0 | ... AC44: =AC203 -> 0
J45: Inventory FGs - Intransit & Stock for Customer's req'mt | L45: =IFERROR(AVERAGEIF(N45:AC45,">0",N45:AC45),) -> 0 | N45: =N204 -> 0 | O45: =O204 -> 0 | P45: =P204 -> 0 | Q45: =Q204 -> 0 | R45: =R204 -> 0 | S45: =S204 -> 0 | T45: =T204 -> 0 | U45: =U204 -> 0 | ... AC45: =AC204 -> 0
J46: Accounts Payable | L46: =IFERROR(AVERAGEIF(N46:AC46,"<0",N46:AC46),) -> 0 | N46: =-N211 -> 0 | O46: =-O211 -> 0 | P46: =-P211 -> 0 | Q46: =-Q211 -> 0 | R46: =-R211 -> 0 | S46: =-S211 -> 0 | T46: =-T211 -> 0 | U46: =-U211 -> 0 | ... AC46: =-AC211 -> 0
J47: Customer Toolings Recoverable | L47: =IFERROR(AVERAGEIF(N47:AC47,">0",N47:AC47),) -> 0 | N47: =N206 -> 0 | O47: =O206 -> 0 | P47: =P206 -> 0 | Q47: =Q206 -> 0 | R47: =R206 -> 0 | S47: =S206 -> 0 | T47: =T206 -> 0 | U47: =U206 -> 0 | ... AC47: =AC206 -> 0
J48: Other Assets/Payables (net, $) | L48: =IFERROR(AVERAGEIF(N48:AC48,"><0",N48:AC48),) -> 0 | N48: =N205-N212 -> 0 | O48: =O205-O212 -> 0 | P48: =P205-P212 -> 0 | Q48: =Q205-Q212 -> 0 | R48: =R205-R212 -> 0 | S48: =S205-S212 -> 0 | T48: =T205-T212 -> 0 | U48: =U205-U212 -> 0 | ... AC48: =AC205-AC212 -> 0
...

Sheet Bgn>>
I407: 10 | J407: Charts for Presentation in USD (Optional)
J433: PNL (USD) | N433: =N11 -> 0 | O433: =O11 -> 0 | P433: =P11 -> 0 | Q433: =Q11 -> 0 | R433: =R11 -> 0 | S433: =S11 -> 0 | T433: =T11 -> 0 | U433: =U11 -> 0 | ... AC433: =AC11 -> 0
N434: =N372 -> 0 | O434: =O372 -> 0 | P434: =P372 -> 0 | Q434: =Q372 -> 0 | R434: =R372 -> 0 | S434: =S372 -> 0 | T434: =T372 -> 0 | U434: =U372 -> 0 | ... AC434: =AC372 -> 0
N435: =N376 -> 0 | O435: =O376 -> 0 | P435: =P376 -> 0 | Q435: =Q376 -> 0 | R435: =R376 -> 0 | S435: =S376 -> 0 | T435: =T376 -> 0 | U435: =U376 -> 0 | ... AC435: =AC376 -> 0
N436: =N377 -> 0 | O436: =O377 -> 0 | P436: =P377 -> 0 | Q436: =Q377 -> 0 | R436: =R377 -> 0 | S436: =S377 -> 0 | T436: =T377 -> 0 | U436: =U377 -> 0 | ... AC436: =AC377 -> 0
N437: =N378 -> 0 | O437: =O378 -> 0 | P437: =P378 -> 0 | Q437: =Q378 -> 0 | R437: =R378 -> 0 | S437: =S378 -> 0 | T437: =T378 -> 0 | U437: =U378 -> 0 | ... AC437: =AC378 -> 0
J439: Cash Flows (USD)
J440: Operating Cash Flow | N440: =N228/$N$365 -> #DIV/0! | O440: =O228/$N$365 -> #DIV/0! | P440: =P228/$N$365 -> #DIV/0! | Q440: =Q228/$N$365 -> #DIV/0! | R440: =R228/$N$365 -> #DIV/0! | S440: =S228/$N$365 -> #DIV/0! | T440: =T228/$N$365 -> #DIV/0! | U440: =U228/$N$365 -> #DIV/0! | ... AC440: =AC228/$N$365 -> #DIV/0!
J441: Investing Cash Flow | N441: =N232/$N$365 -> #DIV/0! | O441: =O232/$N$365 -> #DIV/0! | P441: =P232/$N$365 -> #DIV/0! | Q441: =Q232/$N$365 -> #DIV/0! | R441: =R232/$N$365 -> #DIV/0! | S441: =S232/$N$365 -> #DIV/0! | T441: =T232/$N$365 -> #DIV/0! | U441: =U232/$N$365 -> #DIV/0! | ... AC441: =AC232/$N$365 -> #DIV/0!
J442: Financing Cash Flow | N442: =N237/$N$365 -> #DIV/0! | O442: =O237/$N$365 -> #DIV/0! | P442: =P237/$N$365 -> #DIV/0! | Q442: =Q237/$N$365 -> #DIV/0! | R442: =R237/$N$365 -> #DIV/0! | S442: =S237/$N$365 -> #DIV/0! | T442: =T237/$N$365 -> #DIV/0! | U442: =U237/$N$365 -> #DIV/0! | ... AC442: =AC237/$N$365 -> #DIV/0!
J443: Cumulative CF Ops+Investmt (Proj only) | N443: =SUM($N440:N441) -> #DIV/0! | O443: =SUM($N440:O441) -> #DIV/0! | P443: =SUM($N440:P441) -> #DIV/0! | Q443: =SUM($N440:Q441) -> #DIV/0! | R443: =SUM($N440:R441) -> #DIV/0! | S443: =SUM($N440:S441) -> #DIV/0! | T443: =SUM($N440:T441) -> #DIV/0! | U443: =SUM($N440:U441) -> #DIV/0! | ... AC443: =SUM($N440:AC441) -> #DIV/0!
J445: Working Capital (USD)
N446: =N40/$N$365 -> #DIV/0! | O446: =O40/$N$365 -> #DIV/0! | P446: =P40/$N$365 -> #DIV/0! | Q446: =Q40/$N$365 -> #DIV/0! | R446: =R40/$N$365 -> #DIV/0! | S446: =S40/$N$365 -> #DIV/0! | T446: =T40/$N$365 -> #DIV/0! | U446: =U40/$N$365 -> #DIV/0! | ... AC446: =AC40/$N$365 -> #DIV/0!
N447: =N41/$N$365 -> #DIV/0! | O447: =O41/$N$365 -> #DIV/0! | P447: =P41/$N$365 -> #DIV/0! | Q447: =Q41/$N$365 -> #DIV/0! | R447: =R41/$N$365 -> #DIV/0! | S447: =S41/$N$365 -> #DIV/0! | T447: =T41/$N$365 -> #DIV/0! | U447: =U41/$N$365 -> #DIV/0! | ... AC447: =AC41/$N$365 -> #DIV/0!
N448: =N46/$N$365 -> #DIV/0! | O448: =O46/$N$365 -> #DIV/0! | P448: =P46/$N$365 -> #DIV/0! | Q448: =Q46/$N$365 -> #DIV/0! | R448: =R46/$N$365 -> #DIV/0! | S448: =S46/$N$365 -> #DIV/0! | T448: =T46/$N$365 -> #DIV/0! | U448: =U46/$N$365 -> #DIV/0! | ... AC448: =AC46/$N$365 -> #DIV/0!
N449: =N47/$N$365 -> #DIV/0! | O449: =O47/$N$365 -> #DIV/0! | P449: =P47/$N$365 -> #DIV/0! | Q449: =Q47/$N$365 -> #DIV/0! | R449: =R47/$N$365 -> #DIV/0! | S449: =S47/$N$365 -> #DIV/0! | T449: =T47/$N$365 -> #DIV/0! | U449: =U47/$N$365 -> #DIV/0! | ... AC449: =AC47/$N$365 -> #DIV/0!
N450: =N48/$N$365 -> #DIV/0! | O450: =O48/$N$365 -> #DIV/0! | P450: =P48/$N$365 -> #DIV/0! | Q450: =Q48/$N$365 -> #DIV/0! | R450: =R48/$N$365 -> #DIV/0! | S450: =S48/$N$365 -> #DIV/0! | T450: =T48/$N$365 -> #DIV/0! | U450: =U48/$N$365 -> #DIV/0! | ... AC450: =AC48/$N$365 -> #DIV/0!
N451: =N49/$N$365 -> #DIV/0! | O451: =O49/$N$365 -> #DIV/0! | P451: =P49/$N$365 -> #DIV/0! | Q451: =Q49/$N$365 -> #DIV/0! | R451: =R49/$N$365 -> #DIV/0! | S451: =S49/$N$365 -> #DIV/0! | T451: =T49/$N$365 -> #DIV/0! | U451: =U49/$N$365 -> #DIV/0! | ... AC451: =AC49/$N$365 -> #DIV/0!
J452: Working Capital (Year-end balance) | N452: =N38/$N$365 -> #DIV/0! | O452: =O38/$N$365 -> #DIV/0! | P452: =P38/$N$365 -> #DIV/0! | Q452: =Q38/$N$365 -> #DIV/0! | R452: =R38/$N$365 -> #DIV/0! | S452: =S38/$N$365 -> #DIV/0! | T452: =T38/$N$365 -> #DIV/0! | U452: =U38/$N$365 -> #DIV/0! | ... AC452: =AC38/$N$365 -> #DIV/0!
N453: =N39 -> 0 | O453: =O39 -> 0 | P453: =P39 -> 0 | Q453: =Q39 -> 0 | R453: =R39 -> 0 | S453: =S39 -> 0 | T453: =T39 -> 0 | U453: =U39 -> 0 | ... AC453: =AC39 -> 0

Sheet <<End
I407: 10 | J407: Charts for Presentation in USD (Optional)
J433: PNL (USD) | N433: =N11 -> 0 | O433: =O11 -> 0 | P433: =P11 -> 0 | Q433: =Q11 -> 0 | R433: =R11 -> 0 | S433: =S11 -> 0 | T433: =T11 -> 0 | U433: =U11 -> 0 | ... AC433: =AC11 -> 0
N434: =N372 -> 0 | O434: =O372 -> 0 | P434: =P372 -> 0 | Q434: =Q372 -> 0 | R434: =R372 -> 0 | S434: =S372 -> 0 | T434: =T372 -> 0 | U434: =U372 -> 0 | ... AC434: =AC372 -> 0
N435: =N376 -> 0 | O435: =O376 -> 0 | P435: =P376 -> 0 | Q435: =Q376 -> 0 | R435: =R376 -> 0 | S435: =S376 -> 0 | T435: =T376 -> 0 | U435: =U376 -> 0 | ... AC435: =AC376 -> 0
N436: =N377 -> 0 | O436: =O377 -> 0 | P436: =P377 -> 0 | Q436: =Q377 -> 0 | R436: =R377 -> 0 | S436: =S377 -> 0 | T436: =T377 -> 0 | U436: =U377 -> 0 | ... AC436: =AC377 -> 0
N437: =N378 -> 0 | O437: =O378 -> 0 | P437: =P378 -> 0 | Q437: =Q378 -> 0 | R437: =R378 -> 0 | S437: =S378 -> 0 | T437: =T378 -> 0 | U437: =U378 -> 0 | ... AC437: =AC378 -> 0
J439: Cash Flows (USD)
J440: Operating Cash Flow | N440: =N228/$N$365 -> #DIV/0! | O440: =O228/$N$365 -> #DIV/0! | P440: =P228/$N$365 -> #DIV/0! | Q440: =Q228/$N$365 -> #DIV/0! | R440: =R228/$N$365 -> #DIV/0! | S440: =S228/$N$365 -> #DIV/0! | T440: =T228/$N$365 -> #DIV/0! | U440: =U228/$N$365 -> #DIV/0! | ... AC440: =AC228/$N$365 -> #DIV/0!
J441: Investing Cash Flow | N441: =N232/$N$365 -> #DIV/0! | O441: =O232/$N$365 -> #DIV/0! | P441: =P232/$N$365 -> #DIV/0! | Q441: =Q232/$N$365 -> #DIV/0! | R441: =R232/$N$365 -> #DIV/0! | S441: =S232/$N$365 -> #DIV/0! | T441: =T232/$N$365 -> #DIV/0! | U441: =U232/$N$365 -> #DIV/0! | ... AC441: =AC232/$N$365 -> #DIV/0!
J442: Financing Cash Flow | N442: =N237/$N$365 -> #DIV/0! | O442: =O237/$N$365 -> #DIV/0! | P442: =P237/$N$365 -> #DIV/0! | Q442: =Q237/$N$365 -> #DIV/0! | R442: =R237/$N$365 -> #DIV/0! | S442: =S237/$N$365 -> #DIV/0! | T442: =T237/$N$365 -> #DIV/0! | U442: =U237/$N$365 -> #DIV/0! | ... AC442: =AC237/$N$365 -> #DIV/0!
J443: Cumulative CF Ops+Investmt (Proj only) | N443: =SUM($N440:N441) -> #DIV/0! | O443: =SUM($N440:O441) -> #DIV/0! | P443: =SUM($N440:P441) -> #DIV/0! | Q443: =SUM($N440:Q441) -> #DIV/0! | R443: =SUM($N440:R441) -> #DIV/0! | S443: =SUM($N440:S441) -> #DIV/0! | T443: =SUM($N440:T441) -> #DIV/0! | U443: =SUM($N440:U441) -> #DIV/0! | ... AC443: =SUM($N440:AC441) -> #DIV/0!
J445: Working Capital (USD)
N446: =N40/$N$365 -> #DIV/0! | O446: =O40/$N$365 -> #DIV/0! | P446: =P40/$N$365 -> #DIV/0! | Q446: =Q40/$N$365 -> #DIV/0! | R446: =R40/$N$365 -> #DIV/0! | S446: =S40/$N$365 -> #DIV/0! | T446: =T40/$N$365 -> #DIV/0! | U446: =U40/$N$365 -> #DIV/0! | ... AC446: =AC40/$N$365 -> #DIV/0!
N447: =N41/$N$365 -> #DIV/0! | O447: =O41/$N$365 -> #DIV/0! | P447: =P41/$N$365 -> #DIV/0! | Q447: =Q41/$N$365 -> #DIV/0! | R447: =R41/$N$365 -> #DIV/0! | S447: =S41/$N$365 -> #DIV/0! | T447: =T41/$N$365 -> #DIV/0! | U447: =U41/$N$365 -> #DIV/0! | ... AC447: =AC41/$N$365 -> #DIV/0!
N448: =N46/$N$365 -> #DIV/0! | O448: =O46/$N$365 -> #DIV/0! | P448: =P46/$N$365 -> #DIV/0! | Q448: =Q46/$N$365 -> #DIV/0! | R448: =R46/$N$365 -> #DIV/0! | S448: =S46/$N$365 -> #DIV/0! | T448: =T46/$N$365 -> #DIV/0! | U448: =U46/$N$365 -> #DIV/0! | ... AC448: =AC46/$N$365 -> #DIV/0!
N449: =N47/$N$365 -> #DIV/0! | O449: =O47/$N$365 -> #DIV/0! | P449: =P47/$N$365 -> #DIV/0! | Q449: =Q47/$N$365 -> #DIV/0! | R449: =R47/$N$365 -> #DIV/0! | S449: =S47/$N$365 -> #DIV/0! | T449: =T47/$N$365 -> #DIV/0! | U449: =U47/$N$365 -> #DIV/0! | ... AC449: =AC47/$N$365 -> #DIV/0!
N450: =N48/$N$365 -> #DIV/0! | O450: =O48/$N$365 -> #DIV/0! | P450: =P48/$N$365 -> #DIV/0! | Q450: =Q48/$N$365 -> #DIV/0! | R450: =R48/$N$365 -> #DIV/0! | S450: =S48/$N$365 -> #DIV/0! | T450: =T48/$N$365 -> #DIV/0! | U450: =U48/$N$365 -> #DIV/0! | ... AC450: =AC48/$N$365 -> #DIV/0!
N451: =N49/$N$365 -> #DIV/0! | O451: =O49/$N$365 -> #DIV/0! | P451: =P49/$N$365 -> #DIV/0! | Q451: =Q49/$N$365 -> #DIV/0! | R451: =R49/$N$365 -> #DIV/0! | S451: =S49/$N$365 -> #DIV/0! | T451: =T49/$N$365 -> #DIV/0! | U451: =U49/$N$365 -> #DIV/0! | ... AC451: =AC49/$N$365 -> #DIV/0!
J452: Working Capital (Year-end balance) | N452: =N38/$N$365 -> #DIV/0! | O452: =O38/$N$365 -> #DIV/0! | P452: =P38/$N$365 -> #DIV/0! | Q452: =Q38/$N$365 -> #DIV/0! | R452: =R38/$N$365 -> #DIV/0! | S452: =S38/$N$365 -> #DIV/0! | T452: =T38/$N$365 -> #DIV/0! | U452: =U38/$N$365 -> #DIV/0! | ... AC452: =AC38/$N$365 -> #DIV/0!

Sheet PPT1

Sheet PPT2
B7: Exchange rate: | C7: 1
B10: LTR ($M) | C10: =K12 -> 0 | H10: Project Summary & Investment Evaluation | J10: InUSD | K10: M
B11: GP MARGIN $ | C11: =K14 -> 0 | D11: GP% | E11: =J15 -> 0 | H11: Project PNL & Funding | J11: Project Total
B12: EBITDA $ | C12: =K16 -> 0 | D12: EBITDA % | E12: =J17 -> 0 | H12: Revenue - Parts | I12: Years of Rev: 5 yrs | J12: =SFP254v1.5_CONSOLIDATION!L372 -> 0 | K12: =J12/$C$7/1000000 -> 0
B13: NPV | C13: =K32 -> 0 | D13: % of LTR | E13: =C13/$C$10 -> #DIV/0! | H13: COPA% | J13: =SFP254v1.5_CONSOLIDATION!L373 -> 0 | K13: =J13 -> 0
B14: TOTAL INVESTMENT | C14: =C15+C16 -> 0 | D14: % of LTR | E14: =C14/$C$10 -> #DIV/0! | H14: Gross Profit | J14: =SFP254v1.5_CONSOLIDATION!L374 -> 0 | K14: =J14/$C$7/1000000 -> 0
B15: §CUSTOMER PAID | C15: =K43 -> 0 | D15: % of Total | E15: =C15/$C$14 -> #DIV/0! | H15: GP % | J15: =SFP254v1.5_CONSOLIDATION!L375 -> 0 | K15: =J15 -> 0
B16: §ENNOVI CAPEX | C16: =K20 -> 0 | D16: % of Total | E16: =C16/$C$14 -> #DIV/0! | H16: EBITDA (Parts + Tooling) | J16: =SFP254v1.5_CONSOLIDATION!L376 -> 0 | K16: =J16/$C$7/1000000 -> 0
B17: ROI | C17: ="Original ROI is "&J31 -> Original ROI is 0 yrs | H17: EBITDA% of total revenue (Parts + Tooling) | J17: =SFP254v1.5_CONSOLIDATION!L377 -> 0 | K17: =J17 -> 0
B18: VOLUME VALIDATION | C18: Customer forecast | D18: Safety | E18: -0.1 | H18: EBIT% of total revenue (Parts + Tooling) | J18: =SFP254v1.5_CONSOLIDATION!L378 -> 0 | K18: =J18 -> 0
B19: EXCEPTIONAL CONDITIONS | C19: NA | H19: Project Cash Flow (Operations, WC & Investments) | J19: =SFP254v1.5_CONSOLIDATION!L379 -> 0 | K19: =J19/$C$7/1000000 -> 0
H20: Project Investment - Capex | I20: Useful Life@10yrs | J20: =SFP254v1.5_CONSOLIDATION!L380 -> 0 | K20: =J20/$C$7/1000000 -> 0
H21: Project Investment - Tool Deficit/Invest + Amortization (if any) | J21: =SFP254v1.5_CONSOLIDATION!L381 -> 0 | K21: =J21/$C$7 -> 0
H22: Annual Funding Gap | J22: =SFP254v1.5_CONSOLIDATION!L382 -> 0 | K22: =J22/$C$7/1000000 -> 0
H23: Peak Funding Gap | J23: =SFP254v1.5_CONSOLIDATION!L383 -> 0 | K23: =J23/$C$7/1000000 -> 0
J24: =SFP254v1.5_CONSOLIDATION!L384 -> 0 | K24: =J24/$C$7 -> 0
H25: Other Key Metrics: | J25: =SFP254v1.5_CONSOLIDATION!L385 -> 0 | K25: =J25/$C$7 -> 0
H26: Internal Cost Improvemt/(Deteriortn):Matrl + Process | I26: Inputed in PNL/ROI | J26: =SFP254v1.5_CONSOLIDATION!L386 -> 0 | K26: =J26/$C$7 -> 0
H27: Excess Working Capital Charge, if any | I27: Not imputed in ROI | J27: =SFP254v1.5_CONSOLIDATION!L387 -> 0 | K27: =J27/$C$7 -> 0
J28: =SFP254v1.5_CONSOLIDATION!L388 -> 0 | K28: =J28/$C$7 -> 0
H29: Project Returns | J29: =SFP254v1.5_CONSOLIDATION!L389 -> 0 | K29: =J29/$C$7 -> 0
H30: Cumulative Project Cash Flow (CPCF) | I30: CPCF Multiple: 0.4x | J30: =SFP254v1.5_CONSOLIDATION!L390 -> 0 | K30: =J30/$C$7/1000000 -> 0
H31: ROI (Payback Period) Years | J31: =SFP254v1.5_CONSOLIDATION!L391 -> 0 yrs | K31: =J31 -> 0 yrs
H32: Net Present Value (NPV) | I32: WACC@15% | J32: =SFP254v1.5_CONSOLIDATION!L392 -> 0 | K32: =J32/$C$7/1000000 -> 0
I33: IRR: 13.8% | J33: =SFP254v1.5_CONSOLIDATION!L393 -> 0
H34: Working Capital (Annual Average) | J34: =SFP254v1.5_CONSOLIDATION!L394 -> 0 | K34: =J34/$C$7/1000000 -> 0
H35: WC % Revenue | J35: =SFP254v1.5_CONSOLIDATION!L395 | K35: =J35
H36: Accounts Receivable | J36: =SFP254v1.5_CONSOLIDATION!L396 -> 0 | K36: =J36/$C$7/1000000 -> 0
H37: Total Inventory | J37: =SFP254v1.5_CONSOLIDATION!L397 -> 0 | K37: =J37/$C$7/1000000 -> 0
H38: Inventory - RM/ PI/ Packg | J38: =SFP254v1.5_CONSOLIDATION!L398 -> 0 | K38: =J38/$C$7/1000000 -> 0
H39: Inventory- WIP | J39: =SFP254v1.5_CONSOLIDATION!L399 -> 0 | K39: =J39/$C$7/1000000 -> 0
H40: Inventory FGs - Stock for Interplex's req'mt | J40: =SFP254v1.5_CONSOLIDATION!L400 -> 0 | K40: =J40/$C$7/1000000 -> 0
H41: Inventory FGs - Intransit & Stock for Customer's req'mt | J41: =SFP254v1.5_CONSOLIDATION!L401 -> 0 | K41: 0
H42: Accounts Payable | J42: =SFP254v1.5_CONSOLIDATION!L402 -> 0 | K42: =J42/$C$7/1000000 -> 0
H43: Customer Toolings Recoverable | J43: =SFP254v1.5_CONSOLIDATION!L403 -> 0 | K43: =J43/$C$7/1000000 -> 0
H44: Other Assets/Payables (net, $) | J44: =SFP254v1.5_CONSOLIDATION!L404 -> 0 | K44: 0
H45: Unamortized Balance Tool/Auto Co-Invest | I45: OK,Fully Amortized | J45: =SFP254v1.5_CONSOLIDATION!L405 -> 0 | K45: 0

Sheet PPT2 CM
B7: Exchange rate: | C7: ='PPT2'!C7 -> 1
B10: LTR ($M) | C10: =K12 -> 60.48432 | H10: Project Summary & Investment Evaluation | J10: TOTAL | K10: InUSD
B11: GP MARGIN $ | C11: =K14 -> 11.996067 | D11: GP% | E11: =J15 -> 0.1983335 | H11: Project PNL & Funding | J11: Project Total
B12: EBITDA $ | C12: =K16 -> 11.426445 | D12: EBITDA % | E12: =J17 -> 0.18650573 | H12: Revenue - Parts | I12: Years of Rev: 5 yrs | J12: 60484320 | K12: =J12/$C$7/1000000 -> 60.48432
B13: NPV | C13: =K32 -> 2.9551966 | D13: % of LTR | E13: =C13/$C$10 -> 0.048858888 | H13: COPA% | J13: 0.45354564 | K13: =J13 -> 0.45354564
B14: TOTAL INVESTMENT | C14: =C15+C16 -> 2.9188 | D14: % of LTR | E14: =C14/$C$10 -> 0.048257135 | H14: Gross Profit | J14: 11996067 | K14: =J14/$C$7/1000000 -> 11.996067
B15: §CUSTOMER PAID | C15: =K43 -> 1.0488 | D15: % of Total | E15: =C15/$C$14 -> 0.35932575 | H15: GP % | J15: 0.1983335 | K15: =J15 -> 0.1983335
B16: §ENNOVI CAPEX | C16: =K20 -> 1.87 | D16: % of Total | E16: =C16/$C$14 -> 0.64067425 | H16: EBITDA (Parts + Tooling) | J16: 11426445 | K16: =J16/$C$7/1000000 -> 11.426445
B17: ROI | C17: ="Contribution ROI is "&J31 -> Contribution ROI is 3.2 yrs | H17: EBITDA% of total revenue (Parts + Tooling) | J17: 0.18650573 | K17: =J17 -> 0.18650573
B18: VOLUME VALIDATION | C18: Customer forecast | D18: Safety | E18: -0.1 | H18: EBIT% of total revenue (Parts + Tooling) | J18: 0.15598305 | K18: =J18 -> 0.15598305
B19: EXCEPTIONAL CONDITIONS | C19: NA | H19: Project Cash Flow (Operations, WC & Investments) | J19: 6980333.8 | K19: =J19/$C$7/1000000 -> 6.9803338
H20: Project Investment - Capex | I20: Useful Life@10yrs | J20: 1870000 | K20: =J20/$C$7/1000000 -> 1.87
H21: Project Investment - Tool Deficit/Invest + Amortization (if any) | J21: 534400 | K21: =J21/$C$7 -> 534400
H22: Annual Funding Gap | J22: -2272569.5 | K22: =J22/$C$7/1000000 -> -2.2725695
H23: Peak Funding Gap | J23: -3952726.2 | K23: =J23/$C$7/1000000 -> -3.9527262
K24: =J24/$C$7 -> 0
H25: Other Key Metrics: | K25: =J25/$C$7 -> 0
H26: Internal Cost Improvemt/(Deteriortn):Matrl + Process | I26: Inputed in PNL/ROI | J26: 0 | K26: =J26/$C$7 -> 0
H27: Excess Working Capital Charge, if any | I27: Not imputed in ROI | J27: 0 | K27: =J27/$C$7 -> 0
K28: =J28/$C$7 -> 0
H29: Project Returns | K29: =J29/$C$7 -> 0
H30: Cumulative Project Cash Flow (CPCF) | I30: CPCF Multiple: 0.4x | J30: 6980333.8 | K30: =J30/$C$7/1000000 -> 6.9803338
H31: ROI (Payback Period) Years | J31: 3.2 yrs | K31: =J31 -> 3.2 yrs
H32: Net Present Value (NPV) | I32: WACC@15% | J32: 2955196.6 | K32: =J32/$C$7/1000000 -> 2.9551966
I33: IRR: 13.8%
H34: Working Capital (Annual Average) | J34: 1545316.9 | K34: =J34/$C$7/1000000 -> 1.5453169
H35: WC % Revenue | J35: 0.17063433 | K35: =J35 -> 0.17063433
H36: Accounts Receivable | J36: 3038025.2 | K36: =J36/$C$7/1000000 -> 3.0380252
H37: Total Inventory | J37: 537123.68 | K37: =J37/$C$7/1000000 -> 0.53712368
H38: Inventory - RM/ PI/ Packg | J38: 211290.82 | K38: =J38/$C$7/1000000 -> 0.21129082
H39: Inventory- WIP | J39: 259776.63 | K39: =J39/$C$7/1000000 -> 0.25977663
H40: Inventory FGs - Stock for Interplex's req'mt | J40: 66056.238 | K40: =J40/$C$7/1000000 -> 0.066056238
H41: Inventory FGs - Intransit & Stock for Customer's req'mt | J41: 0 | K41: 0
H42: Accounts Payable | J42: -2029832 | K42: =J42/$C$7/1000000 -> -2.029832
H43: Customer Toolings Recoverable | J43: 1048800 | K43: =J43/$C$7/1000000 -> 1.0488
H44: Other Assets/Payables (net, $) | J44: 0 | K44: 0
H45: Unamortized Balance Tool/Auto Co-Invest | I45: OK,Fully Amortized | J45: 267200 | K45: 0

Sheet Combine
C5: Combine
C6: LTR ($M) | D6: ='PPT2 CM'!C10 -> 60.48432
C7: GP MARGIN $ | D7: {=TEXT('PPT2'!C11:C13,"$0.00")&"M / "&TEXT('PPT2 CM'!C11:C13,"$0.00")&"M"} -> $0.00M / $12.00M | E7: GP% | F7: {=TEXT('PPT2'!E11:E13,"0.0%")&" / "&TEXT('PPT2 CM'!E11:E13,"0.0%")} -> 0.0% / 19.8%
C8: EBITDA $ | D8: $0.00M / $11.43M | E8: EBITDA % | F8: 0.0% / 18.7%
C9: NPV | D9: $0.00M / $2.96M | E9: % of LTR | F9: #DIV/0!
C10: TOTAL INVESTMENT | D10: {='PPT2 CM'!C14:C16} -> 2.9188 | E10: % of LTR | F10: {='PPT2 CM'!E14:E16} -> 0.048257135
C11: §CUSTOMER PAID | D11: 1.0488 | E11: % of Total | F11: 0.35932575
C12: §ENNOVI CAPEX | D12: 1.87 | E12: % of Total | F12: 0.64067425
C13: ROI | D13: ="Normal ROI is "&'PPT2'!J31&CHAR(10)&"CM ROI is "&'PPT2 CM'!J31 -> Normal ROI is 0 yrs CM ROI is 3.2 yrs
C14: VOLUME VALIDATION | D14: Customer forecast | E14: Safety | F14: -0.1
C15: EXCEPTIONAL CONDITIONS | D15: ='PPT2 CM'!C19 -> NA

Sheet for summary need
I4: Normal | M4: CM
C5: Part Description | D5: Currency | E5: Proposal Price USD | F5: Total LTR | G5: TL | H5: CAPEX | I5: GP% | J5: EBITDA% | K5: ROI | L5: NPV | M5: GP% | N5: EBITDA% | O5: ROI | P5: NPV
C6: 1089319-10 | D6: USD | E6: 0.368621 | F6: 3105263.3 | G6: 60378.08 | H6: 104904 | I6: 0.057239567 | J6: 0.021815393 | K6: No Full Recovery | L6: -92910.277 | M6: 0.14709237 | N6: 0.13938225 | O6: 3.9 yrs | P6: 82324.303
C7: 1092161-10 | D7: USD | E7: 0.677505 | F7: 5707302.1 | G7: 53501.04 | H7: 167555 | I7: 0.16597545 | J7: 0.12300115 | K7: 4.3 yrs | L7: 107901.61 | M7: 0.22621308 | N7: 0.21240073 | O7: 3 yrs | P7: 348247.84
C13: Total | F13: =SUM(F6:F12) -> 8812565.4 | G13: =SUM(G6:G12) -> 113879.12 | H13: =SUM(H6:H12) -> 272459 | I13: ='PPT2'!E11 -> 0 | J13: ='PPT2'!E12 -> 0 | K13: ='PPT2'!J31 -> 0 yrs | L13: =SUM(L6:L12) -> 14991.332 | M13: ='PPT2 CM'!E11 -> 0.1983335 | N13: ='PPT2 CM'!E12 -> 0.18650573 | O13: ='PPT2 CM'!J31 -> 3.2 yrs | P13: =SUM(P6:P12) -> 430572.15

Sheet PI Summary
A2: Part Description | B2: Currency | C2: Mfg. Cost per piece | D2: Last Yr Selling Price per piece | E2: Total LTR | F2: Customer Investment | G2: Ennovi Investment | H2: Overall GP | I2: Overall GP% | J2: EBITDA | K2: EBITDA% | L2: ROI | M2: NPV | N2: NPI | R2: Part Description | S2: Currency | T2: Mfg. Cost per piece | U2: Last Yr Selling Price per piece | V2: Total LTR | W2: Customer Investment | X2: Ennovi Investment | Y2: Overall GP | Z2: Overall GP% | AA2: EBITDA | AB2: EBITDA% | AC2: ROI | AD2: NPV | AE2: NPI
A3: 1089319-10 | B3: USD | C3: 0.34145891 | D3: 0.368621 | E3: 3105263.3 | F3: 60378.08 | G3: 104904 | H3: 177743.93 | I3: 0.057239567 | J3: 69059.711 | K3: 0.021815393 | L3: No Full Recovery | M3: -92910.277 | N3: 14177.453 | R3: 1089319-10 | S3: USD | T3: 0.31118521 | U3: 0.368621 | V3: 3105263.3 | W3: 60378.08 | X3: 104904 | Y3: 456760.54 | Z3: 0.14709237 | AA3: 441234.22 | AB3: 0.13938225 | AC3: 3.9 yrs | AD3: 82324.303 | AE3: 12871.385
A4: 1089319-10 | B4: Site Currency CNY | C4: 2.3435752 | D4: 2.53 | E4: 21312720 | F4: 414400 | G4: 720000 | H4: 1219930.9 | I4: 0.057239567 | J4: 473985.66 | K4: 0.021815393 | L4: No Full Recovery | M4: -637682.07 | N4: 97305.785 | R4: 1089319-10 | S4: Site Currency CNY | T4: 2.1357941 | U4: 2.53 | V4: 21312720 | W4: 414400 | X4: 720000 | Y4: 3134938.5 | Z4: 0.14709237 | AA4: 3028374.9 | AB4: 0.13938225 | AC4: 3.9 yrs | AD4: 565026.1 | AE4: 88341.694
A5: 1092161-10 | B5: USD | C5: 0.55774111 | D5: 0.677505 | E5: 5707302.1 | F5: 53501.04 | G5: 167555 | H5: 947272.02 | I5: 0.16597545 | J5: 747516.45 | K5: 0.12300115 | L5: 4.3 yrs | M5: 107901.61 | N5: 23039.447 | R5: 1092161-10 | S5: USD | T5: 0.52036067 | U5: 0.677505 | V5: 5707302.1 | W5: 53501.04 | X5: 167555 | Y5: 1291066.4 | Z5: 0.22621308 | AA5: 1262529.9 | AB5: 0.21240073 | AC5: 3 yrs | AD5: 348247.84 | AE5: 21427.743
A6: 1092161-10 | B6: Site Currency CNY | C6: 3.8280104 | D6: 4.65 | E6: 39171600 | F6: 367200 | G6: 1150000 | H6: 6501523.8 | I6: 0.16597545 | J6: 5130517.8 | K6: 0.12300115 | L6: 4.3 yrs | M6: 740573.84 | N6: 158129.36 | R6: 1092161-10 | S6: Site Currency CNY | T6: 3.5714528 | U6: 4.65 | V6: 39171600 | W6: 367200 | X6: 1150000 | Y6: 8861128.1 | Z6: 0.22621308 | AA6: 8665270.1 | AB6: 0.21240073 | AC6: 3 yrs | AD6: 2390170.5 | AE6: 147067.56

Sheet SFP254v1.5_CER (Prog1)
I7: Pre-CER / CER Financial Evaluation | K7: SFP#254 v1.5_16-04-2024 | N7: (standalone template)
J8: Project: - | K8: [Prepared by] | L8: Currency:
J9: ENNOVI/Interplex Production Site: | L9: Note: USD Presentatn in Sectn 9, Charts in Sectn 10 | AB9: Cells for Input (data or formula ) | AC9: Display Only (Do NOT enter)
J10: Overall Check | L10: =IF(OR(L11=0,L11="",L12=0,L12=""),"WARNING: Must enter SOP YYYY & MM below","OK, SOP date entered") -> OK, SOP date entered | N10: =IF(AND(N220="OK",N221="OK",N241="OK",N255="OK",N305="OK",$K$49="OK,Fully Amortized"),"OK","Wrong") -> OK | O10: =IF(AND(O220="OK",O221="OK",O241="OK",O255="OK",O305="OK"),"OK","Wrong") -> OK | P10: =IF(AND(P220="OK",P221="OK",P241="OK",P255="OK",P305="OK"),"OK","Wrong") -> OK | Q10: =IF(AND(Q220="OK",Q221="OK",Q241="OK",Q255="OK",Q305="OK"),"OK","Wrong") -> OK | R10: =IF(AND(R220="OK",R221="OK",R241="OK",R255="OK",R305="OK"),"OK","Wrong") -> OK | S10: =IF(AND(S220="OK",S221="OK",S241="OK",S255="OK",S305="OK"),"OK","Wrong") -> OK | T10: =IF(AND(T220="OK",T221="OK",T241="OK",T255="OK",T305="OK"),"OK","Wrong") -> OK | U10: =IF(AND(U220="OK",U221="OK",U241="OK",U255="OK",U305="OK"),"OK","Wrong") -> OK | V10: =IF(AND(V220="OK",V221="OK",V241="OK",V255="OK",V305="OK"),"OK","Wrong") -> OK | ... AC10: =IF(AND(AC220="OK",AC221="OK",AC241="OK",AC255="OK",AC305="OK"),"OK","Wrong") -> OK
J11: =L8 -> Currency: | K11: SOP Cal Year: | L11: 2025 | N11: =L11-1 -> 2024 | O11: =N11+1 -> 2025 | P11: =O11+1 -> 2026 | Q11: =P11+1 -> 2027 | R11: =Q11+1 -> 2028 | S11: =R11+1 -> 2029 | T11: =S11+1 -> 2030 | U11: =T11+1 -> 2031 | V11: =U11+1 -> 2032 | W11: =V11+1 -> 2033 | X11: =IF(W11=0,0,W11+1) -> 2034 | Y11: =IF(X11=0,0,X11+1) -> 2035 | Z11: =IF(Y11=0,0,Y11+1) -> 2036 | AA11: =IF(Z11=0,0,Z11+1) -> 2037 | AB11: =IF(AA11=0,0,AA11+1) -> 2038 | AC11: =IF(AB11=0,0,AB11+1) -> 2039
K12: SOP Cal Mth: | L12: 6 | N12: Calendar Year | O12: =N12 -> Calendar Year | P12: =O12 -> Calendar Year | Q12: =P12 -> Calendar Year | R12: =Q12 -> Calendar Year | S12: =R12 -> Calendar Year | T12: =S12 -> Calendar Year | U12: =T12 -> Calendar Year | V12: =U12 -> Calendar Year | ... AC12: =AB12 -> Calendar Year
I14: 1 | J14: Project Summary & Investment Evaluation | L14: TOTAL
I15: A | J15: Project PNL & Funding | L15: Project Total
J16: Revenue - Parts | K16: ="Years of Rev: "&COUNTIF(N16:AC16,">0")&" yrs" -> Years of Rev: 0 yrs | L16: =SUM(N16:AC16) -> 0 | N16: =N118 -> 0 | O16: =O118 -> 0 | P16: =P118 -> 0 | Q16: =Q118 -> 0 | R16: =R118 -> 0 | S16: =S118 -> 0 | T16: =T118 -> 0 | U16: =U118 -> 0 | ... AC16: =AC118 -> 0
J17: COPA% | L17: =K125 -> 0 | N17: =N125 -> 0 | O17: =O125 -> 0 | P17: =P125 -> 0 | Q17: =Q125 -> 0 | R17: =R125 -> 0 | S17: =S125 -> 0 | T17: =T125 -> 0 | U17: =U125 -> 0 | ... AC17: =AC125 -> 0
J18: Gross Profit | L18: =SUM(N18:AC18) -> 0 | N18: =N153 -> 0 | O18: =O153 -> 0 | P18: =P153 -> 0 | Q18: =Q153 -> 0 | R18: =R153 -> 0 | S18: =S153 -> 0 | T18: =T153 -> 0 | U18: =U153 -> 0 | ... AC18: =AC153 -> 0
J19: GP % | L19: =IFERROR(L18/L$16,0) -> 0 | N19: =IFERROR(N18/N16,) -> 0 | O19: =IFERROR(O18/O16,) -> 0 | P19: =IFERROR(P18/P16,) -> 0 | Q19: =IFERROR(Q18/Q16,) -> 0 | R19: =IFERROR(R18/R16,) -> 0 | S19: =IFERROR(S18/S16,) -> 0 | T19: =IFERROR(T18/T16,) -> 0 | U19: =IFERROR(U18/U16,) -> 0 | ... AC19: =IFERROR(AC18/AC16,) -> 0
J20: EBITDA (Parts + Tooling) | L20: =SUM(N20:AC20) -> 0 | N20: =N162 -> 0 | O20: =O162 -> 0 | P20: =P162 -> 0 | Q20: =Q162 -> 0 | R20: =R162 -> 0 | S20: =S162 -> 0 | T20: =T162 -> 0 | U20: =U162 -> 0 | ... AC20: =AC162 -> 0
J21: EBITDA% of total revenue (Parts + Tooling) | L21: =IFERROR(L20/(L16+K139),0) -> 0 | N21: =IFERROR(N20/(N16+N139),0) -> 0 | O21: =IFERROR(O20/(O16+O139),0) -> 0 | P21: =IFERROR(P20/(P16+P139),0) -> 0 | Q21: =IFERROR(Q20/(Q16+Q139),0) -> 0 | R21: =IFERROR(R20/(R16+R139),0) -> 0 | S21: =IFERROR(S20/(S16+S139),0) -> 0 | T21: =IFERROR(T20/(T16+T139),0) -> 0 | U21: =IFERROR(U20/(U16+U139),0) -> 0 | ... AC21: =IFERROR(AC20/(AC16+AC139),0) -> 0
J22: EBIT% of total revenue (Parts + Tooling) | L22: =K166 -> 0 | N22: =N166 -> 0 | O22: =O166 -> 0 | P22: =P166 -> 0 | Q22: =Q166 -> 0 | R22: =R166 -> 0 | S22: =S166 -> 0 | T22: =T166 -> 0 | U22: =U166 -> 0 | ... AC22: =AC166 -> 0
J23: Project Cash Flow (Operations, WC & Investments) | L23: =SUM(N23:AC23) -> 0 | N23: =N324 -> 0 | O23: =O324 -> 0 | P23: =P324 -> 0 | Q23: =Q324 -> 0 | R23: =R324 -> 0 | S23: =S324 -> 0 | T23: =T324 -> 0 | U23: =U324 -> 0 | ... AC23: =AC324 -> 0
J24: Project Investment - Capex | K24: ="Useful Life@"&ROUND(L94,2)&"yrs" -> Useful Life@8yrs | L24: =SUM(N24:AC24) -> 0 | N24: =N70 -> 0 | O24: =O70 -> 0 | P24: =P70 -> 0 | Q24: =Q70 -> 0 | R24: =R70 -> 0 | S24: =S70 -> 0 | T24: =T70 -> 0 | U24: =U70 -> 0 | ... AC24: =AC70 -> 0
J25: Project Investment - Tool Deficit/Invest + Amortization (if any) | L25: =SUM(N25:AC25) -> 0 | N25: =SUM(N73,N74) -> 0 | O25: =SUM(O73,O74) -> 0 | P25: =SUM(P73,P74) -> 0 | Q25: =SUM(Q73,Q74) -> 0 | R25: =SUM(R73,R74) -> 0 | S25: =SUM(S73,S74) -> 0 | T25: =SUM(T73,T74) -> 0 | U25: =SUM(U73,U74) -> 0 | ... AC25: =SUM(AC73,AC74) -> 0
J26: =IF(L75>0,"Annual Funding Gap (including IC asset transfer)","Annual Funding Gap") -> Annual Funding Gap | L26: =SUM(N26:AC26) -> 0 | N26: =-N65 -> 0 | O26: =-O65 -> 0 | P26: =-P65 -> 0 | Q26: =-Q65 -> 0 | R26: =-R65 -> 0 | S26: =-S65 -> 0 | T26: =-T65 -> 0 | U26: =-U65 -> 0 | ... AC26: =-AC65 -> 0
J27: =IF(L75>0,"Peak Funding Gap (including IC asset transfer)","Peak Funding Gap") -> Peak Funding Gap | L27: =MIN(N27:AC27) -> 0 | N27: =N274 -> 0 | O27: =O274 -> 0 | P27: =P274 -> 0 | Q27: =Q274 -> 0 | R27: =R274 -> 0 | S27: =S274 -> 0 | T27: =T274 -> 0 | U27: =U274 -> 0 | ... AC27: =AC274 -> 0
J29: Other Key Metrics:
J30: Internal Cost Improvemt/(Deteriortn):Matrl + Process | K30: Inputed in PNL/ROI | L30: =SUM(N30:AC30) -> 0 | N30: =SUM(N123,N132) -> 0 | O30: =SUM(O123,O132) -> 0 | P30: =SUM(P123,P132) -> 0 | Q30: =SUM(Q123,Q132) -> 0 | R30: =SUM(R123,R132) -> 0 | S30: =SUM(S123,S132) -> 0 | T30: =SUM(T123,T132) -> 0 | U30: =SUM(U123,U132) -> 0 | ... AC30: =SUM(AC123,AC132) -> 0
J31: Excess Working Capital Charge, if any | K31: =IF(P107="Yes","Imputed in ROI","Not imputed in ROI") -> Not imputed in ROI | L31: =SUM(N31:AC31) -> 0 | N31: =IF(N167>0,0,N167) -> 0 | O31: =IF(O167>0,0,O167) -> 0 | P31: =IF(P167>0,0,P167) -> 0 | Q31: =IF(Q167>0,0,Q167) -> 0 | R31: =IF(R167>0,0,R167) -> 0 | S31: =IF(S167>0,0,S167) -> 0 | T31: =IF(T167>0,0,T167) -> 0 | U31: =IF(U167>0,0,U167) -> 0 | ... AC31: =IF(AC167>0,0,AC167) -> 0
I33: B | J33: Project Returns
J34: Cumulative Project Cash Flow (CPCF) | K34: =IFERROR(CONCATENATE("CPCF Multiple: ",ROUND(L34/L65,1),"x"),"MOIC Multiple") -> MOIC Multiple | L34: =AC34 -> 0 | N34: =N325 -> 0 | O34: =O325 -> 0 | P34: =P325 -> 0 | Q34: =Q325 -> 0 | R34: =R325 -> 0 | S34: =S325 -> 0 | T34: =T325 -> 0 | U34: =U325 -> 0 | ... AC34: =AC325 -> 0
J35: ROI (Payback Period) Years | L35: =IF($L$335="No Full Recovery","No Full Recovery",CONCATENATE(ROUND(SUM(N326:AC326),1)," yrs")) -> 0 yrs | N35: =IF($L$335="No Full Recovery","",ROUND(N326,2)&" yrs") -> 0 yrs | O35: =IF($L$335="No Full Recovery","",ROUND(O326,2)&" yrs") -> 0 yrs | P35: =IF($L$335="No Full Recovery","",ROUND(P326,2)&" yrs") -> 0 yrs | Q35: =IF($L$335="No Full Recovery","",ROUND(Q326,2)&" yrs") -> 0 yrs | R35: =IF($L$335="No Full Recovery","",ROUND(R326,2)&" yrs") -> 0 yrs | S35: =IF($L$335="No Full Recovery","",ROUND(S326,2)&" yrs") -> 0 yrs | T35: =IF($L$335="No Full Recovery","",ROUND(T326,2)&" yrs") -> 0 yrs | U35: =IF($L$335="No Full Recovery","",ROUND(U326,2)&" yrs") -> 0 yrs | ... AC35: =IF($L$335="No Full Recovery","",ROUND(AC326,2)&" yrs") -> 0 yrs
J36: Net Present Value (NPV) | K36: =CONCATENATE("WACC@",$L$98*100,"%") -> WACC@15% | L36: =AC36 -> 0 | N36: =SUM($N327:N327) -> 0 | O36: =SUM($N327:O327) -> 0 | P36: =SUM($N327:P327) -> 0 | Q36: =SUM($N327:Q327) -> 0 | R36: =SUM($N327:R327) -> 0 | S36: =SUM($N327:S327) -> 0 | T36: =SUM($N327:T327) -> 0 | U36: =SUM($N327:U327) -> 0 | ... AC36: =SUM($N327:AC327) -> 0
K37: =CONCATENATE("IRR: ",ROUND($L$334*100,1),"%") -> IRR: 0%
I38: C | J38: Working Capital (Annual Average) | L38: =IFERROR(AVERAGEIF(O38:AC38,">100",O38:AC38),) -> 0 | N38: =SUM(N40:N48)-N41 -> 0 | O38: =SUM(O40:O48)-O41 -> 0 | P38: =SUM(P40:P48)-P41 -> 0 | Q38: =SUM(Q40:Q48)-Q41 -> 0 | R38: =SUM(R40:R48)-R41 -> 0 | S38: =SUM(S40:S48)-S41 -> 0 | T38: =SUM(T40:T48)-T41 -> 0 | U38: =SUM(U40:U48)-U41 -> 0 | ... AC38: =SUM(AC40:AC48)-AC41 -> 0
J39: WC % Revenue | L39: =IFERROR(SUM(N38:AC38)/SUM(N16:AC16),"") | N39: =IFERROR(N38/N16*N78/365,"") | O39: =IFERROR(O38/O16*O78/365,"") | P39: =IFERROR(P38/P16*P78/365,"") | Q39: =IFERROR(Q38/Q16*Q78/365,"") | R39: =IFERROR(R38/R16*R78/365,"") | S39: =IFERROR(S38/S16*S78/365,"") | T39: =IFERROR(T38/T16*T78/365,"") | U39: =IFERROR(U38/U16*U78/365,"") | ... AC39: =IFERROR(AC38/AC16*AC78/365,"")
J40: Accounts Receivable | L40: =IFERROR(AVERAGEIF(N40:AC40,">0",N40:AC40),) -> 0 | N40: =N200 -> 0 | O40: =O200 -> 0 | P40: =P200 -> 0 | Q40: =Q200 -> 0 | R40: =R200 -> 0 | S40: =S200 -> 0 | T40: =T200 -> 0 | U40: =U200 -> 0 | ... AC40: =AC200 -> 0
J41: Total Inventory | L41: =IFERROR(AVERAGEIF(N41:AC41,">0",N41:AC41),) -> 0 | N41: =SUM(N42:N45) -> 0 | O41: =SUM(O42:O45) -> 0 | P41: =SUM(P42:P45) -> 0 | Q41: =SUM(Q42:Q45) -> 0 | R41: =SUM(R42:R45) -> 0 | S41: =SUM(S42:S45) -> 0 | T41: =SUM(T42:T45) -> 0 | U41: =SUM(U42:U45) -> 0 | ... AC41: =SUM(AC42:AC45) -> 0
J42: Inventory - RM/ PI/ Packg | L42: =IFERROR(AVERAGEIF(N42:AC42,">0",N42:AC42),) -> 0 | N42: =N201 -> 0 | O42: =O201 -> 0 | P42: =P201 -> 0 | Q42: =Q201 -> 0 | R42: =R201 -> 0 | S42: =S201 -> 0 | T42: =T201 -> 0 | U42: =U201 -> 0 | ... AC42: =AC201 -> 0
J43: Inventory- WIP | L43: =IFERROR(AVERAGEIF(N43:AC43,">0",N43:AC43),) -> 0 | N43: =N202 -> 0 | O43: =O202 -> 0 | P43: =P202 -> 0 | Q43: =Q202 -> 0 | R43: =R202 -> 0 | S43: =S202 -> 0 | T43: =T202 -> 0 | U43: =U202 -> 0 | ... AC43: =AC202 -> 0
J44: Inventory FGs - Stock for ENNOVI/Interplex's req'mt | L44: =IFERROR(AVERAGEIF(N44:AC44,">0",N44:AC44),) -> 0 | N44: =N203 -> 0 | O44: =O203 -> 0 | P44: =P203 -> 0 | Q44: =Q203 -> 0 | R44: =R203 -> 0 | S44: =S203 -> 0 | T44: =T203 -> 0 | U44: =U203 -> 0 | ... AC44: =AC203 -> 0
J45: Inventory FGs - Intransit & Stock for Customer's req'mt | L45: =IFERROR(AVERAGEIF(N45:AC45,">0",N45:AC45),) -> 0 | N45: =N204 -> 0 | O45: =O204 -> 0 | P45: =P204 -> 0 | Q45: =Q204 -> 0 | R45: =R204 -> 0 | S45: =S204 -> 0 | T45: =T204 -> 0 | U45: =U204 -> 0 | ... AC45: =AC204 -> 0
J46: Accounts Payable | L46: =IFERROR(AVERAGEIF(N46:AC46,"<0",N46:AC46),) -> 0 | N46: =-N211 -> 0 | O46: =-O211 -> 0 | P46: =-P211 -> 0 | Q46: =-Q211 -> 0 | R46: =-R211 -> 0 | S46: =-S211 -> 0 | T46: =-T211 -> 0 | U46: =-U211 -> 0 | ... AC46: =-AC211 -> 0
J47: Customer Toolings Recoverable | L47: =IFERROR(AVERAGEIF(N47:AC47,">0",N47:AC47),) -> 0 | N47: =N206 -> 0 | O47: =O206 -> 0 | P47: =P206 -> 0 | Q47: =Q206 -> 0 | R47: =R206 -> 0 | S47: =S206 -> 0 | T47: =T206 -> 0 | U47: =U206 -> 0 | ... AC47: =AC206 -> 0
J48: Other Assets/Payables (net, $) | L48: =IFERROR(AVERAGEIF(N48:AC48,"><0",N48:AC48),) -> 0 | N48: =N205-N212 -> 0 | O48: =O205-O212 -> 0 | P48: =P205-P212 -> 0 | Q48: =Q205-Q212 -> 0 | R48: =R205-R212 -> 0 | S48: =S205-S212 -> 0 | T48: =T205-T212 -> 0 | U48: =U205-U212 -> 0 | ... AC48: =AC205-AC212 -> 0
J49: Unamortized Balance Tool/Auto Co-Invest | K49: =K297 -> OK,Fully Amortized | L49: =IFERROR(AVERAGEIF(N49:AC49,">0",N49:AC49),) -> 0 | N49: =N207 -> 0 | O49: =O207 -> 0 | P49: =P207 -> 0 | Q49: =Q207 -> 0 | R49: =R207 -> 0 | S49: =S207 -> 0 | T49: =T207 -> 0 | U49: =U207 -> 0 | ... AC49: =AC207 -> 0
...

Sheet SFP254v1.5_CER (Prog2)
I7: Pre-CER / CER Financial Evaluation | K7: SFP#254 v1.5_16-04-2024 | N7: (standalone template)
J8: Project: - | K8: [Prepared by] | L8: Currency:
J9: ENNOVI/Interplex Production Site: | L9: Note: USD Presentatn in Sectn 9, Charts in Sectn 10 | AB9: Cells for Input (data or formula ) | AC9: Display Only (Do NOT enter)
J10: Overall Check | L10: =IF(OR(L11=0,L11="",L12=0,L12=""),"WARNING: Must enter SOP YYYY & MM below","OK, SOP date entered") -> OK, SOP date entered | N10: =IF(AND(N220="OK",N221="OK",N241="OK",N255="OK",N305="OK",$K$49="OK,Fully Amortized"),"OK","Wrong") -> OK | O10: =IF(AND(O220="OK",O221="OK",O241="OK",O255="OK",O305="OK"),"OK","Wrong") -> OK | P10: =IF(AND(P220="OK",P221="OK",P241="OK",P255="OK",P305="OK"),"OK","Wrong") -> OK | Q10: =IF(AND(Q220="OK",Q221="OK",Q241="OK",Q255="OK",Q305="OK"),"OK","Wrong") -> OK | R10: =IF(AND(R220="OK",R221="OK",R241="OK",R255="OK",R305="OK"),"OK","Wrong") -> OK | S10: =IF(AND(S220="OK",S221="OK",S241="OK",S255="OK",S305="OK"),"OK","Wrong") -> OK | T10: =IF(AND(T220="OK",T221="OK",T241="OK",T255="OK",T305="OK"),"OK","Wrong") -> OK | U10: =IF(AND(U220="OK",U221="OK",U241="OK",U255="OK",U305="OK"),"OK","Wrong") -> OK | V10: =IF(AND(V220="OK",V221="OK",V241="OK",V255="OK",V305="OK"),"OK","Wrong") -> OK | ... AC10: =IF(AND(AC220="OK",AC221="OK",AC241="OK",AC255="OK",AC305="OK"),"OK","Wrong") -> OK
J11: =L8 -> Currency: | K11: SOP Cal Year: | L11: 2025 | N11: =L11-1 -> 2024 | O11: =N11+1 -> 2025 | P11: =O11+1 -> 2026 | Q11: =P11+1 -> 2027 | R11: =Q11+1 -> 2028 | S11: =R11+1 -> 2029 | T11: =S11+1 -> 2030 | U11: =T11+1 -> 2031 | V11: =U11+1 -> 2032 | W11: =V11+1 -> 2033 | X11: =IF(W11=0,0,W11+1) -> 2034 | Y11: =IF(X11=0,0,X11+1) -> 2035 | Z11: =IF(Y11=0,0,Y11+1) -> 2036 | AA11: =IF(Z11=0,0,Z11+1) -> 2037 | AB11: =IF(AA11=0,0,AA11+1) -> 2038 | AC11: =IF(AB11=0,0,AB11+1) -> 2039
K12: SOP Cal Mth: | L12: 6 | N12: Calendar Year | O12: =N12 -> Calendar Year | P12: =O12 -> Calendar Year | Q12: =P12 -> Calendar Year | R12: =Q12 -> Calendar Year | S12: =R12 -> Calendar Year | T12: =S12 -> Calendar Year | U12: =T12 -> Calendar Year | V12: =U12 -> Calendar Year | ... AC12: =AB12 -> Calendar Year
I14: 1 | J14: Project Summary & Investment Evaluation | L14: TOTAL
I15: A | J15: Project PNL & Funding | L15: Project Total
J16: Revenue - Parts | K16: ="Years of Rev: "&COUNTIF(N16:AC16,">0")&" yrs" -> Years of Rev: 0 yrs | L16: =SUM(N16:AC16) -> 0 | N16: =N118 -> 0 | O16: =O118 -> 0 | P16: =P118 -> 0 | Q16: =Q118 -> 0 | R16: =R118 -> 0 | S16: =S118 -> 0 | T16: =T118 -> 0 | U16: =U118 -> 0 | ... AC16: =AC118 -> 0
J17: COPA% | L17: =K125 -> 0 | N17: =N125 -> 0 | O17: =O125 -> 0 | P17: =P125 -> 0 | Q17: =Q125 -> 0 | R17: =R125 -> 0 | S17: =S125 -> 0 | T17: =T125 -> 0 | U17: =U125 -> 0 | ... AC17: =AC125 -> 0
J18: Gross Profit | L18: =SUM(N18:AC18) -> 0 | N18: =N153 -> 0 | O18: =O153 -> 0 | P18: =P153 -> 0 | Q18: =Q153 -> 0 | R18: =R153 -> 0 | S18: =S153 -> 0 | T18: =T153 -> 0 | U18: =U153 -> 0 | ... AC18: =AC153 -> 0
J19: GP % | L19: =IFERROR(L18/L$16,0) -> 0 | N19: =IFERROR(N18/N16,) -> 0 | O19: =IFERROR(O18/O16,) -> 0 | P19: =IFERROR(P18/P16,) -> 0 | Q19: =IFERROR(Q18/Q16,) -> 0 | R19: =IFERROR(R18/R16,) -> 0 | S19: =IFERROR(S18/S16,) -> 0 | T19: =IFERROR(T18/T16,) -> 0 | U19: =IFERROR(U18/U16,) -> 0 | ... AC19: =IFERROR(AC18/AC16,) -> 0
J20: EBITDA (Parts + Tooling) | L20: =SUM(N20:AC20) -> 0 | N20: =N162 -> 0 | O20: =O162 -> 0 | P20: =P162 -> 0 | Q20: =Q162 -> 0 | R20: =R162 -> 0 | S20: =S162 -> 0 | T20: =T162 -> 0 | U20: =U162 -> 0 | ... AC20: =AC162 -> 0
J21: EBITDA% of total revenue (Parts + Tooling) | L21: =IFERROR(L20/(L16+K139),0) -> 0 | N21: =IFERROR(N20/(N16+N139),0) -> 0 | O21: =IFERROR(O20/(O16+O139),0) -> 0 | P21: =IFERROR(P20/(P16+P139),0) -> 0 | Q21: =IFERROR(Q20/(Q16+Q139),0) -> 0 | R21: =IFERROR(R20/(R16+R139),0) -> 0 | S21: =IFERROR(S20/(S16+S139),0) -> 0 | T21: =IFERROR(T20/(T16+T139),0) -> 0 | U21: =IFERROR(U20/(U16+U139),0) -> 0 | ... AC21: =IFERROR(AC20/(AC16+AC139),0) -> 0
J22: EBIT% of total revenue (Parts + Tooling) | L22: =K166 -> 0 | N22: =N166 -> 0 | O22: =O166 -> 0 | P22: =P166 -> 0 | Q22: =Q166 -> 0 | R22: =R166 -> 0 | S22: =S166 -> 0 | T22: =T166 -> 0 | U22: =U166 -> 0 | ... AC22: =AC166 -> 0
J23: Project Cash Flow (Operations, WC & Investments) | L23: =SUM(N23:AC23) -> 0 | N23: =N324 -> 0 | O23: =O324 -> 0 | P23: =P324 -> 0 | Q23: =Q324 -> 0 | R23: =R324 -> 0 | S23: =S324 -> 0 | T23: =T324 -> 0 | U23: =U324 -> 0 | ... AC23: =AC324 -> 0
J24: Project Investment - Capex | K24: ="Useful Life@"&ROUND(L94,2)&"yrs" -> Useful Life@8yrs | L24: =SUM(N24:AC24) -> 0 | N24: =N70 -> 0 | O24: =O70 -> 0 | P24: =P70 -> 0 | Q24: =Q70 -> 0 | R24: =R70 -> 0 | S24: =S70 -> 0 | T24: =T70 -> 0 | U24: =U70 -> 0 | ... AC24: =AC70 -> 0
J25: Project Investment - Tool Deficit/Invest + Amortization (if any) | L25: =SUM(N25:AC25) -> 0 | N25: =SUM(N73,N74) -> 0 | O25: =SUM(O73,O74) -> 0 | P25: =SUM(P73,P74) -> 0 | Q25: =SUM(Q73,Q74) -> 0 | R25: =SUM(R73,R74) -> 0 | S25: =SUM(S73,S74) -> 0 | T25: =SUM(T73,T74) -> 0 | U25: =SUM(U73,U74) -> 0 | ... AC25: =SUM(AC73,AC74) -> 0
J26: =IF(L75>0,"Annual Funding Gap (including IC asset transfer)","Annual Funding Gap") -> Annual Funding Gap | L26: =SUM(N26:AC26) -> 0 | N26: =-N65 -> 0 | O26: =-O65 -> 0 | P26: =-P65 -> 0 | Q26: =-Q65 -> 0 | R26: =-R65 -> 0 | S26: =-S65 -> 0 | T26: =-T65 -> 0 | U26: =-U65 -> 0 | ... AC26: =-AC65 -> 0
J27: =IF(L75>0,"Peak Funding Gap (including IC asset transfer)","Peak Funding Gap") -> Peak Funding Gap | L27: =MIN(N27:AC27) -> 0 | N27: =N274 -> 0 | O27: =O274 -> 0 | P27: =P274 -> 0 | Q27: =Q274 -> 0 | R27: =R274 -> 0 | S27: =S274 -> 0 | T27: =T274 -> 0 | U27: =U274 -> 0 | ... AC27: =AC274 -> 0
J29: Other Key Metrics:
